<?xml version="1.0"?>
<robot xmlns:xacro="http://www.ros.org/wiki/xacro" name="amr">

    <!-- 定义属性 -->
    <!-- 定义 STL 比例，用于缩放 STL 文件的网格 -->
    <xacro:property name="stl_scale" value="0.001 0.001 0.001"/>
    <!-- 定义各个部分的颜色: 底盘、驱动轮、万向轮、激光雷达 -->
    <xacro:property name="base_color" value="0.5 0.5 0.5 1.0"/> <!-- 本体的颜色：灰色 -->
    <xacro:property name="wheel_color" value="0.7 0.2 0.2 1.0"/> <!-- 左右驱动轮的颜色：红色 -->
    <xacro:property name="caster_color" value="0.0 0.0 0.0 1.0"/> <!-- 前后万向轮的颜色：黑色 -->
    <xacro:property name="lidar_color" value="0.0 0.0 0.0 1.0"/> <!-- 激光雷达的颜色：黑色 -->

    <!-- 虚拟根链接 (base_footprint) -->
    <!-- base_footprint 是虚拟的参考框架，用来定义机器人在地面上的位置和姿态 -->
    <link name="base_footprint">
        <visual>
            <origin xyz="0 0 0" rpy="0 0 0" />
            <geometry>
                <box size="0.05 0.05 0.001" />
            </geometry>
        </visual>
    </link>

    <!-- base_link 是底盘的主要框架，与虚拟根链接 base_footprint 通过固定关节连接 -->
    <joint name="base_footprint_to_base_link" type="fixed">
        <parent link="base_footprint"/> <!-- 连接到 base_footprint -->
        <child link="base_link"/> <!-- base_link 作为子链接 -->
        <origin xyz="0 0 0" rpy="0 0 0"/> <!-- 原点和旋转设置，保持位置和方向不变 -->
    </joint>

    <!-- 底盘 (base_link) -->
    <!-- 
        参数说明:
            - 形状: 长方体
            - 尺寸: 长66.8厘米, 宽57.8厘米, 高18厘米
            - 离地间隙: 2厘米
            - STL 网格文件: base_link.stl
    -->
    <link name="base_link">
        <visual>
            <origin xyz="0 0 0.02" rpy="0 0 0" />
            <geometry>
                <!-- 视觉形状 -->
                <mesh filename="package://amr_description/meshes/base_link.stl" scale="${stl_scale}"/>
            </geometry>
            <material name="grey">
                <color rgba="${base_color}"/> <!-- 设置底盘颜色 -->
            </material>
        </visual>
        <collision>
            <geometry>
                <!-- 与视觉形状一致，用于碰撞检测 -->
                <mesh filename="package://amr_description/meshes/base_link.stl" scale="${stl_scale}"/>
            </geometry>
        </collision>
    </link>


    <!-- 左右驱动轮 -->
    <!-- 
        参数说明:
            - 半径: 9厘米
            - 宽度: 4.5厘米
            - 颜色: 黑色
            - STL 网格文件: left_wheel.stl
                           right_wheel.stl
    -->
    <link name="left_wheel">
        <visual>
            <geometry>
                <mesh filename="package://amr_description/meshes/left_wheel.stl" scale="${stl_scale}"/>
            </geometry>
            <material name="red">
                <color rgba="${wheel_color}"/> <!-- 设置轮子的颜色 -->
            </material>
        </visual>
        <collision>
            <geometry>
                <mesh filename="package://amr_description/meshes/left_wheel.stl" scale="${stl_scale}"/>
            </geometry>
        </collision>
    </link>

    <joint name="base_link_to_left_wheel" type="continuous"> <!-- 关节类型为 continuous 表示连续旋转 -->
        <parent link="base_link" />
        <child link="left_wheel" />
        <origin xyz="0 0.23215 0.09"/> <!-- 根据底盘和轮子尺寸设置左轮的位置和离地距离 -->
        <axis xyz="0 1 0" /> <!-- 左轮沿 y 轴旋转 -->
    </joint>

    <link name="right_wheel">
        <visual>
            <geometry>
                <mesh filename="package://amr_description/meshes/right_wheel.stl" scale="${stl_scale}"/>
            </geometry>
            <material name="red">
                <color rgba="${wheel_color}"/> <!-- 颜色设置一致 -->
            </material>
        </visual>
        <collision>
            <geometry>
                <mesh filename="package://amr_description/meshes/right_wheel.stl" scale="${stl_scale}"/>
            </geometry>
        </collision>
    </link>

    <joint name="base_link_to_right_wheel" type="continuous">
        <parent link="base_link" />
        <child link="right_wheel" />
        <origin xyz="0 -0.23215 0.09"/>
        <axis xyz="0 1 0" /> <!-- 右轮沿 y 轴旋转 -->
    </joint>


    <!-- 前后万向轮叉架 -->
    <link name="front_fork">
        <visual>
            <geometry>
                <mesh filename="package://amr_description/meshes/front_fork.stl" scale="${stl_scale}"/>
            </geometry>
            <material name="grey"/>
        </visual>
        <collision>
            <geometry>
                <mesh filename="package://amr_description/meshes/front_fork.stl" scale="${stl_scale}"/>
            </geometry>
        </collision>
    </link>

    <!-- 万向节的 joint -->
    <joint name="base_link_to_front_fork" type="continuous">
        <parent link="base_link"/> <!-- 父链接为车体 -->
        <child link="front_fork"/> <!-- 子链接为叉架 -->
        <origin xyz="0.264 0 0.0399" rpy="0 0 0"/> <!-- 叉架相对于车体的原点和姿态 -->
        <axis xyz="0 0 1"/> <!-- 允许叉架围绕 Z 轴自由旋转（万向功能） -->
    </joint>

    <link name="back_fork">
        <visual>
            <geometry>
                <mesh filename="package://amr_description/meshes/back_fork.stl" scale="${stl_scale}"/>
            </geometry>
            <material name="grey"/>
        </visual>
        <collision>
            <geometry>
                <mesh filename="package://amr_description/meshes/back_fork.stl" scale="${stl_scale}"/>
            </geometry>
        </collision>
    </link>

    <joint name="base_link_to_back_fork" type="continuous">
        <parent link="base_link"/> <!-- 父链接为车体 -->
        <child link="back_fork"/> <!-- 子链接为叉架 -->
        <origin xyz="-0.264 0 0.0399" rpy="0 0 0"/> <!-- 叉架相对于车体的原点和姿态 -->
        <axis xyz="0 0 1"/> <!-- 允许叉架围绕 Z 轴自由旋转（万向功能） -->
    </joint>

    <!-- 前后万向轮 (支撑轮) -->
    <!-- 
        参数说明:
            - 颜色: 黑色
            - STL 网格文件: front_caster.stl
                            back_caster.stl
    -->
    <link name="front_caster">
        <visual>
            <geometry>
                <mesh filename="package://amr_description/meshes/front_caster.stl" scale="${stl_scale}"/>
            </geometry>
            <material name="black">
                <color rgba="${caster_color}"/> <!-- 设置前万向轮的颜色 -->
            </material>
        </visual>
        <collision>
            <geometry>
                <mesh filename="package://amr_description/meshes/front_caster.stl" scale="${stl_scale}"/>
            </geometry>
        </collision>
    </link>

    <joint name="front_fork_to_front_caster" type="continuous">
        <parent link="front_fork" />
        <child link="front_caster" />
        <origin xyz="-0.012 0 -0.0239"/> <!-- 前万向轮放置在底盘前部，离地适中 -->
        <axis xyz="0 1 0"/> <!-- 前万向轮自由旋转 -->
    </joint>

    <link name="back_caster">
        <visual>
            <geometry>
                <mesh filename="package://amr_description/meshes/back_caster.stl" scale="${stl_scale}"/>
            </geometry>
            <material name="black">
                <color rgba="${caster_color}"/> <!-- 设置后万向轮的颜色 -->
            </material>
        </visual>
        <collision>
            <geometry>
                <mesh filename="package://amr_description/meshes/back_caster.stl" scale="${stl_scale}"/>
            </geometry>
        </collision>
    </link>

    <joint name="back_fork_to_back_caster" type="continuous">
        <parent link="back_fork" />
        <child link="back_caster" />
        <origin xyz="-0.012 0 -0.0239"/> <!-- 后万向轮放置在底盘后部，对称于前万向轮 -->
        <axis xyz="0 1 0"/> <!-- 后万向轮自由旋转 -->
    </joint>

    <!-- 激光雷达 (laser) -->
    <!-- 
        参数说明:
            - 高度: 3.885厘米
            - 半径: 7.7厘米
            - STL 网格文件: laser.stl
    -->
    <link name="laser">
        <visual>
            <geometry>
                <mesh filename="package://amr_description/meshes/laser.stl" scale="${stl_scale}"/>
            </geometry>
            <material name="black">
                <color rgba="${lidar_color}"/>
            </material>
        </visual>
        <collision>
            <geometry>
                <mesh filename="package://amr_description/meshes/laser.stl" scale="${stl_scale}"/>
            </geometry>
        </collision>
    </link>

    <!-- laser 通过固定关节连接到 base_link -->
    <joint name="base_link_to_laser" type="fixed">
        <parent link="base_link"/>
        <child link="laser"/>
        <origin xyz="0.2815 0 0.17223265" rpy="0 0 0"/> <!-- 激光雷达相对于车体的原点和姿态 -->
    </joint>

</robot>
